Traceback (most recent call last):
  File "E:\Python\physics-python-and-pi\venv\Lib\site-packages\jupyter_core\utils\__init__.py", line 154, in wrapped
    asyncio.get_running_loop()
    ~~~~~~~~~~~~~~~~~~~~~~~~^^
RuntimeError: no running event loop

During handling of the above exception, another exception occurred:

Traceback (most recent call last):
  File "E:\Python\physics-python-and-pi\venv\Lib\site-packages\jupyter_cache\executors\utils.py", line 58, in single_nb_execution
    executenb(
    ~~~~~~~~~^
        nb,
        ^^^
    ...<4 lines>...
        **kwargs,
        ^^^^^^^^^
    )
    ^
  File "E:\Python\physics-python-and-pi\venv\Lib\site-packages\nbclient\client.py", line 1319, in execute
    return NotebookClient(nb=nb, resources=resources, km=km, **kwargs).execute()
           ~~~~~~~~~~~~~~~~~~~~~~~~~~~~~~~~~~~~~~~~~~~~~~~~~~~~~~~~~~~~~~~~~~~^^
  File "E:\Python\physics-python-and-pi\venv\Lib\site-packages\jupyter_core\utils\__init__.py", line 158, in wrapped
    return loop.run_until_complete(inner)
           ~~~~~~~~~~~~~~~~~~~~~~~^^^^^^^
  File "C:\Users\Vladyslav\AppData\Local\Programs\Python\Python313\Lib\asyncio\base_events.py", line 725, in run_until_complete
    return future.result()
           ~~~~~~~~~~~~~^^
  File "E:\Python\physics-python-and-pi\venv\Lib\site-packages\nbclient\client.py", line 709, in async_execute
    await self.async_execute_cell(
        cell, index, execution_count=self.code_cells_executed + 1
    )
  File "E:\Python\physics-python-and-pi\venv\Lib\site-packages\nbclient\client.py", line 1062, in async_execute_cell
    await self._check_raise_for_error(cell, cell_index, exec_reply)
  File "E:\Python\physics-python-and-pi\venv\Lib\site-packages\nbclient\client.py", line 918, in _check_raise_for_error
    raise CellExecutionError.from_cell_and_msg(cell, exec_reply_content)
nbclient.exceptions.CellExecutionError: An error occurred while executing the following cell:
------------------
# Create a sample figure
df = px.data.iris()
fig = px.scatter(df, x="sepal_width", y="sepal_length", color="species")

------------------


[31m---------------------------------------------------------------------------[39m
[31mNameError[39m                                 Traceback (most recent call last)
[36mCell[39m[36m [39m[32mIn[10][39m[32m, line 2[39m
[32m      1[39m [38;5;66;03m# Create a sample figure[39;00m
[32m----> [39m[32m2[39m df = [43mpx[49m.data.iris()
[32m      3[39m fig = px.scatter(df, x=[33m"[39m[33msepal_width[39m[33m"[39m, y=[33m"[39m[33msepal_length[39m[33m"[39m, color=[33m"[39m[33mspecies[39m[33m"[39m)

[31mNameError[39m: name 'px' is not defined

