Traceback (most recent call last):
  File "/Users/vladyakovliev/Desktop/Science/quantopia/venv/lib/python3.13/site-packages/jupyter_core/utils/__init__.py", line 154, in wrapped
    asyncio.get_running_loop()
    ~~~~~~~~~~~~~~~~~~~~~~~~^^
RuntimeError: no running event loop

During handling of the above exception, another exception occurred:

Traceback (most recent call last):
  File "/Users/vladyakovliev/Desktop/Science/quantopia/venv/lib/python3.13/site-packages/jupyter_cache/executors/utils.py", line 58, in single_nb_execution
    executenb(
    ~~~~~~~~~^
        nb,
        ^^^
    ...<4 lines>...
        **kwargs,
        ^^^^^^^^^
    )
    ^
  File "/Users/vladyakovliev/Desktop/Science/quantopia/venv/lib/python3.13/site-packages/nbclient/client.py", line 1319, in execute
    return NotebookClient(nb=nb, resources=resources, km=km, **kwargs).execute()
           ~~~~~~~~~~~~~~~~~~~~~~~~~~~~~~~~~~~~~~~~~~~~~~~~~~~~~~~~~~~~~~~~~~~^^
  File "/Users/vladyakovliev/Desktop/Science/quantopia/venv/lib/python3.13/site-packages/jupyter_core/utils/__init__.py", line 158, in wrapped
    return loop.run_until_complete(inner)
           ~~~~~~~~~~~~~~~~~~~~~~~^^^^^^^
  File "/Library/Frameworks/Python.framework/Versions/3.13/lib/python3.13/asyncio/base_events.py", line 721, in run_until_complete
    return future.result()
           ~~~~~~~~~~~~~^^
  File "/Users/vladyakovliev/Desktop/Science/quantopia/venv/lib/python3.13/site-packages/nbclient/client.py", line 709, in async_execute
    await self.async_execute_cell(
        cell, index, execution_count=self.code_cells_executed + 1
    )
  File "/Users/vladyakovliev/Desktop/Science/quantopia/venv/lib/python3.13/site-packages/nbclient/client.py", line 1062, in async_execute_cell
    await self._check_raise_for_error(cell, cell_index, exec_reply)
  File "/Users/vladyakovliev/Desktop/Science/quantopia/venv/lib/python3.13/site-packages/nbclient/client.py", line 918, in _check_raise_for_error
    raise CellExecutionError.from_cell_and_msg(cell, exec_reply_content)
nbclient.exceptions.CellExecutionError: An error occurred while executing the following cell:
------------------
import seaborn as sns
import matplotlib.pyplot as plt
import numpy as np
from mpl_toolkits.mplot3d import Axes3D
import plotly.graph_objects as go
import sympy as sp
------------------


[31m---------------------------------------------------------------------------[39m
[31mModuleNotFoundError[39m                       Traceback (most recent call last)
[36mCell[39m[36m [39m[32mIn[1][39m[32m, line 6[39m
[32m      4[39m [38;5;28;01mfrom[39;00m[38;5;250m [39m[34;01mmpl_toolkits[39;00m[34;01m.[39;00m[34;01mmplot3d[39;00m[38;5;250m [39m[38;5;28;01mimport[39;00m Axes3D
[32m      5[39m [38;5;28;01mimport[39;00m[38;5;250m [39m[34;01mplotly[39;00m[34;01m.[39;00m[34;01mgraph_objects[39;00m[38;5;250m [39m[38;5;28;01mas[39;00m[38;5;250m [39m[34;01mgo[39;00m
[32m----> [39m[32m6[39m [38;5;28;01mimport[39;00m[38;5;250m [39m[34;01msympy[39;00m[38;5;250m [39m[38;5;28;01mas[39;00m[38;5;250m [39m[34;01msp[39;00m

[31mModuleNotFoundError[39m: No module named 'sympy'

